<?xml version="1.0" ?>
<!-- This is the main XML file that defines a humanoid robot model in MuJoCo physics simulator -->
<mujoco model="Humanoid">
  <!-- Basic settings for how angles are measured and physics are calculated -->
  <!-- calculating intertia from the geometry of the body parts-->
  <compiler angle="degree" inertiafromgeom="true" coordinate="local"/>
  <!-- Sets how often the physics simulation updates (every 0.005 seconds) -->
  <option timestep="0.005"/>

  <!-- Visual settings for how the simulation looks -->
  <visual>
    <!-- Main camera view settings:
         - znear/zfar: Defines how close and far the camera can see (0.1 to 2000 units)
         - Like setting the minimum and maximum viewing distance -->
    <map znear="0.1" zfar="2000"/>
    <!-- Adds a slight haze effect to the background -->
    <rgba haze="0.15 0.25 0.35 1"/>
    <!-- Sets the quality of shadows -->
    <quality shadowsize="4096"/>
    <!-- Default spectator camera position and screen settings:
         - offwidth/offheight: Sets the viewport resolution to 2560x1440
         - elevation: Camera angle above the ground (-20 degrees)
         - azimuth: Camera rotation around vertical axis (120 degrees) -->
    <global offwidth="2560" offheight="1440" elevation="-20" azimuth="120"/>
    <!-- Sets the size of various visual indicators -->
    <scale forcewidth="0.1" contactwidth="0.1" contactheight="0.1" connect="0.1" com="0.1"/>
  </visual>

  <!-- Sets the size of the visible workspace -->
  <statistic extent="50" center="0 0 1"/>

  <!-- Defines visual assets like textures and materials -->
  <asset>
    <!-- Creates a gradient skybox background -->
    <texture type="skybox" builtin="gradient" rgb1="0.3 0.5 0.7" rgb2="0 0 0" width="512" height="512"/>
    <!-- Creates a checkered floor texture -->
    <texture name="texplane" type="2d" builtin="checker" rgb1=".2 .3 .4" rgb2=".1 0.15 0.2" width="512" height="512" mark="cross" markrgb=".8 .8 .8"/>
    <!-- Defines materials using the textures -->
    <material name="floor" texture="texplane" texuniform="true"/>
    <material name="body" rgba="1 1 1 1"/>
  </asset>

  <!-- Default settings for all joints and body parts -->
  <default>
    <!-- Joint settings: how stiff and damped the joints are, and that the joints are limited in degrees -->
    <joint armature="1" damping="5" limited="true"/>
    <!-- Physical properties for all geometric shapes (body parts):
         - conaffinity="1" and contype="1": Enables collision detection between body parts
         - condim="3": Enables normal forces and friction in both surface directions
         - margin="0.001": Creates a small collision buffer for stable physics
         - rgba="1 1 1 1": Sets color to white (red=1, green=1, blue=1, alpha=1)
         - material="body": Uses the "body" material defined in assets -->
    <geom conaffinity="1" condim="3" contype="1" margin="0.001" rgba="1 1 1 1" material="body"/>
    <!-- Motor settings for joint control:
         - ctrllimited="true": Enables limits on how much power the motors can apply
         - ctrlrange="-1 1": Sets the control range from -100% to +100% power
         This prevents motors from applying infinite force and makes the simulation more realistic -->
    <motor ctrllimited="true" ctrlrange="-1 1"/>
  </default>

  <!-- The main body of the robot and the world -->
  <worldbody>
    <!-- Adds a light source -->
    <light diffuse=".5 .5 .5" pos="0 0 3" dir="0 0 -1"/>
    <!-- Creates the floor -->
    <geom name="floor" pos="0 0 0" size="50 50 .125" type="plane" material="floor" condim="3" friction="1.0 0.1 0.01"/>
    
    <!-- Site for overall COM visualization -->
    <site name="overall_com" pos="0 0 1" size="0.04" rgba="1 0 0 1" type="sphere"/>
    
    <!-- Main torso of the robot (unified body) -->
    <body name="torso" pos="0 0 1.0">
      <!-- Allows the torso to move freely in all directions -->
      <freejoint name="root"/>
      <!-- Creates the torso geometry -->
      <geom name="torso" type="capsule" fromto="0 -.21 0 0 .21 0" size="0.2" mass="16" rgba="1 1 1 0.5" friction="1.0 0.1 0.01"/>
      <!-- Adds a tracking camera that follows the robot:
           - pos="0 -15 5": Camera positioned 15 units behind and 5 units above the robot
           - mode="fixed": Camera maintains its position relative to the robot's torso
           - zaxis="0 0 1": Camera looks forward along the z-axis
           This gives a consistent "third-person" view as the robot moves -->
      <camera name="track" mode="fixed" pos="0 -15 5" zaxis="0 0 1"/>
      
      <!-- Right leg assembly -->
      <!-- postion is relative to the parent body -->
      <body name="thigh_right" pos="0 -0.3 -0.04">
        <!-- Hip joints for right leg (3 degrees of freedom)
             Original biomechanical ranges were:
             - hip_x: -25° to 5° (side-to-side movement)
             - hip_z: -60° to 35° (rotation)
             - hip_y: -110° to 20° (forward/back movement) -->
        <joint name="hip_x_right" axis="1 0 0" range="-180 180" pos="0 0 0" stiffness="1000" damping="100"/>
        <joint name="hip_z_right" axis="0 0 1" range="-180 180" pos="0 0 0" stiffness="1000" damping="100"/>
        <joint name="hip_y_right" axis="0 1 0" range="-180 180" pos="0 0 0" stiffness="1000" damping="100"/>
        <!-- Right thigh geometry -->
        <geom name="thigh_right" type="capsule" fromto="0 0 0 0 0.01 -0.34" size="0.25" mass="4.5" rgba="1 1 1 1" friction="1.0 0.1 0.01"/>
        
        <!-- Right shin (lower leg) -->
        <body name="shin_right" pos="0 0.01 -0.403">
          <!-- Knee joint (originally -160° to 2°) -->
          <joint name="knee_right" pos="0 0 .02" axis="0 -1 0" range="-180 180" stiffness="1000" damping="100"/>
          <!-- Right shin geometry -->
          <geom name="shin_right" type="capsule" fromto="0 0 0 0 0 -0.35" size="0.25" mass="2.5" rgba="1 1 1 1" friction="1.0 0.1 0.01" condim="6"/>
        </body>
      </body>

      <!-- Left leg assembly (mirror of right leg) -->
      <body name="thigh_left" pos="0 0.3 -0.04">
        <!-- Hip joints for left leg (3 degrees of freedom)
             Original biomechanical ranges were:
             - hip_x: -25° to 5° (side-to-side movement)
             - hip_z: -60° to 35° (rotation)
             - hip_y: -110° to 20° (forward/back movement) -->
        <joint name="hip_x_left" axis="-1 0 0" range="-180 180" pos="0 0 0" stiffness="1000" damping="100"/>
        <joint name="hip_z_left" axis="0 0 -1" range="-180 180" pos="0 0 0" stiffness="1000" damping="100"/>
        <joint name="hip_y_left" axis="0 1 0" range="-180 180" pos="0 0 0" stiffness="1000" damping="100"/>
        <!-- Left thigh geometry -->
        <geom name="thigh_left" type="capsule" fromto="0 0 0 0 -0.01 -0.34" size="0.25" mass="4.5" rgba="1 1 1 1" friction="1.0 0.1 0.01"/>
        
        <!-- Left shin (lower leg) -->
        <body name="shin_left" pos="0 -0.01 -0.403">
          <!-- Knee joint (originally -160° to 2°) -->
          <joint name="knee_left" pos="0 0 .02" axis="0 -1 0" range="-180 180" stiffness="1000" damping="100"/>
          <!-- Left shin geometry -->
          <geom name="shin_left" type="capsule" fromto="0 0 0 0 0 -0.35" size="0.25" mass="2.5" rgba="1 1 1 1" friction="1.0 0.1 0.01" condim="6"/>
        </body>
      </body>
    </body>
  </worldbody>

  <!-- Defines the position actuators (servos) that control each joint -->
  <!-- COMMENTED OUT FOR DIRECT JOINT CONTROL VIA data.qpos
  <actuator>
    <!-- Position controllers for right leg with full ±180° range -->
    <position name="hip_x_right" joint="hip_x_right" kp="19.6" ctrlrange="-180 180"/>
    <position name="hip_z_right" joint="hip_z_right" kp="20.0" ctrlrange="-180 180"/>
    <position name="hip_y_right" joint="hip_y_right" kp="19.6" ctrlrange="-180 180"/>
    <position name="knee_right"  joint="knee_right"  kp="20.2" ctrlrange="-180 180"/>
    
    <!-- Position controllers for left leg with full ±180° range -->
    <position name="hip_x_left"  joint="hip_x_left"  kp="19.6" ctrlrange="-180 180"/>
    <position name="hip_z_left"  joint="hip_z_left"  kp="20.0" ctrlrange="-180 180"/>
    <position name="hip_y_left"  joint="hip_y_left"  kp="19.6" ctrlrange="-180 180"/>
    <position name="knee_left"   joint="knee_left"   kp="20.2" ctrlrange="-180 180"/>
  </actuator>
  -->
</mujoco>
